Workbook

Sheet 00_Readme
A1: ACQUISITION DECISION SYSTEM
A3: Current call: NOT YET — bounded secondary experiment only (max 5 hrs/week).
A4: Start here: ACQUISITION/ideal-business-fit.md — operator fit map before any listing search.
A6: TAB GUIDE
A7: 01_Archetype_Scorecard — vertical fit, Fit class (Buy/Conditional/Never), weighted Tier
A8: 02_Target_Size_Bands — SDE/EBITDA/EV bands and affordability calculator
A9: 03_Operator_Readiness — financing, runway, willingness gates
A10: 04_Deal_Pipeline — real listings only
A11: 05_Deal_Scorecard — per-deal weighted score + Day-to-day litmus gate + Pursue/Watch/Kill
A12: 06_Business_Risk_Diligence — personnel, ops, customer, revenue quality
A13: 07_Diligence_Memo — one-page memo template per deal
A14: 08_Time_Budget — weekly hours across Path A, Path B, acquisition
... A52: See ACQUISITION/README.md, ideal-business-fit.md, and ownership-challenges.md for full rules.

Sheet 01_Archetype_Scorecard
A1: Vertical | B1: Workflow | C1: Info Arbitrage | D1: Pricing | E1: Automation | F1: Discovery | G1: Marketplace | H1: Labor Burden (-) | I1: Sales Hero (-) | J1: Weighted Score | K1: Fit class | L1: Tier | M1: Notes
A2: Factor weights (ref) | B2: 0.15 | C2: 0.15 | D2: 0.15 | E2: 0.15 | F2: 0.1 | G2: 0.1 | H2: 0.1 | I2: 0.1
A3: Freight Brokerage | B3: 9 | C3: 9 | D3: 10 | E3: 8 | F3: 8 | G3: 10 | H3: 4 | I3: 5 | J3: =ROUND((B3*$B$2+C3*$C$2+D3*$D$2+E3*$E$2+F3*$F$2+G3*$G$2+(10-H3)*$H$2+(10-I3)*$I$2)/SUM($B$2:$I$2),1) | K3: Conditional | L3: =IF(J3>=7.5,"Tier 1",IF(J3>=5.5,"Tier 2","Tier 3"))
A4: Construction Estimating | B4: 10 | C4: 8 | D4: 7 | E4: 9 | F4: 8 | G4: 3 | H4: 4 | I4: 3 | J4: =ROUND((B4*$B$2+C4*$C$2+D4*$D$2+E4*$E$2+F4*$F$2+G4*$G$2+(10-H4)*$H$2+(10-I4)*$I$2)/SUM($B$2:$I$2),1) | K4: Buy | L4: =IF(J4>=7.5,"Tier 1",IF(J4>=5.5,"Tier 2","Tier 3"))
A5: Permit Expediting | B5: 10 | C5: 9 | D5: 8 | E5: 10 | F5: 7 | G5: 2 | H5: 3 | I5: 4 | J5: =ROUND((B5*$B$2+C5*$C$2+D5*$D$2+E5*$E$2+F5*$F$2+G5*$G$2+(10-H5)*$H$2+(10-I5)*$I$2)/SUM($B$2:$I$2),1) | K5: Buy | L5: =IF(J5>=7.5,"Tier 1",IF(J5>=5.5,"Tier 2","Tier 3"))
A6: Industrial Distribution | B6: 8 | C6: 8 | D6: 10 | E6: 8 | F6: 8 | G6: 5 | H6: 4 | I6: 5 | J6: =ROUND((B6*$B$2+C6*$C$2+D6*$D$2+E6*$E$2+F6*$F$2+G6*$G$2+(10-H6)*$H$2+(10-I6)*$I$2)/SUM($B$2:$I$2),1) | K6: Conditional | L6: =IF(J6>=7.5,"Tier 1",IF(J6>=5.5,"Tier 2","Tier 3"))
A7: Specialty Staffing | B7: 7 | C7: 7 | D7: 7 | E7: 7 | F7: 8 | G7: 10 | H7: 8 | I7: 7 | J7: =ROUND((B7*$B$2+C7*$C$2+D7*$D$2+E7*$E$2+F7*$F$2+G7*$G$2+(10-H7)*$H$2+(10-I7)*$I$2)/SUM($B$2:$I$2),1) | K7: Never | L7: =IF(J7>=7.5,"Tier 1",IF(J7>=5.5,"Tier 2","Tier 3"))
A8: Insurance Inspections | B8: 8 | C8: 8 | D8: 8 | E8: 8 | F8: 7 | G8: 2 | H8: 6 | I8: 4 | J8: =ROUND((B8*$B$2+C8*$C$2+D8*$D$2+E8*$E$2+F8*$F$2+G8*$G$2+(10-H8)*$H$2+(10-I8)*$I$2)/SUM($B$2:$I$2),1) | K8: Conditional | L8: =IF(J8>=7.5,"Tier 1",IF(J8>=5.5,"Tier 2","Tier 3"))
A9: Valuation Services | B9: 8 | C9: 10 | D9: 9 | E9: 7 | F9: 9 | G9: 2 | H9: 3 | I9: 5 | J9: =ROUND((B9*$B$2+C9*$C$2+D9*$D$2+E9*$E$2+F9*$F$2+G9*$G$2+(10-H9)*$H$2+(10-I9)*$I$2)/SUM($B$2:$I$2),1) | K9: Buy | L9: =IF(J9>=7.5,"Tier 1",IF(J9>=5.5,"Tier 2","Tier 3"))
A10: Industry Research / Data | B10: 9 | C10: 10 | D10: 9 | E10: 8 | F10: 9 | G10: 1 | H10: 2 | I10: 3 | J10: =ROUND((B10*$B$2+C10*$C$2+D10*$D$2+E10*$E$2+F10*$F$2+G10*$G$2+(10-H10)*$H$2+(10-I10)*$I$2)/SUM($B$2:$I$2),1) | K10: Buy | L10: =IF(J10>=7.5,"Tier 1",IF(J10>=5.5,"Tier 2","Tier 3"))
A11: Vertical SaaS | B11: 8 | C11: 9 | D11: 9 | E11: 10 | F11: 10 | G11: 2 | H11: 2 | I11: 4 | J11: =ROUND((B11*$B$2+C11*$C$2+D11*$D$2+E11*$E$2+F11*$F$2+G11*$G$2+(10-H11)*$H$2+(10-I11)*$I$2)/SUM($B$2:$I$2),1) | K11: Buy | L11: =IF(J11>=7.5,"Tier 1",IF(J11>=5.5,"Tier 2","Tier 3"))
A12: MSP | B12: 6 | C12: 5 | D12: 6 | E12: 6 | F12: 6 | G12: 1 | H12: 8 | I12: 8 | J12: =ROUND((B12*$B$2+C12*$C$2+D12*$D$2+E12*$E$2+F12*$F$2+G12*$G$2+(10-H12)*$H$2+(10-I12)*$I$2)/SUM($B$2:$I$2),1) | K12: Never | L12: =IF(J12>=7.5,"Tier 1",IF(J12>=5.5,"Tier 2","Tier 3"))
A13: HVAC | B13: 4 | C13: 2 | D13: 3 | E13: 2 | F13: 3 | G13: 1 | H13: 9 | I13: 5 | J13: =ROUND((B13*$B$2+C13*$C$2+D13*$D$2+E13*$E$2+F13*$F$2+G13*$G$2+(10-H13)*$H$2+(10-I13)*$I$2)/SUM($B$2:$I$2),1) | K13: Never | L13: =IF(J13>=7.5,"Tier 1",IF(J13>=5.5,"Tier 2","Tier 3"))
A14: Roofing | B14: 4 | C14: 2 | D14: 4 | E14: 2 | F14: 2 | G14: 1 | H14: 10 | I14: 6 | J14: =ROUND((B14*$B$2+C14*$C$2+D14*$D$2+E14*$E$2+F14*$F$2+G14*$G$2+(10-H14)*$H$2+(10-I14)*$I$2)/SUM($B$2:$I$2),1) | K14: Never | L14: =IF(J14>=7.5,"Tier 1",IF(J14>=5.5,"Tier 2","Tier 3"))
... A16: Laundromat | B16: 1 | C16: 1 | D16: 3 | E16: 2 | F16: 1 | G16: 1 | H16: 2 | I16: 1 | J16: =ROUND((B16*$B$2+C16*$C$2+D16*$D$2+E16*$E$2+F16*$F$2+G16*$G$2+(10-H16)*$H$2+(10-I16)*$I$2)/SUM($B$2:$I$2),1) | K16: Never | L16: =IF(J16>=7.5,"Tier 1",IF(J16>=5.5,"Tier 2","Tier 3"))
A19: CATEGORY THEMES (preserved from original workbook)
A20: # | B20: Business type & Theme | C20: Why it fits | D20: Main risk | E20: Target EV
A21: 1 | B21: Vertical logistics / dispatch service with software layer | C21: Direct match to quote-to-dispatch, routing, crew assignment, and pricing work. | D21: Labor, claims, seasonality, customer concentration.
A22: 2 | B22: Broker / intermediary business with ugly workflow | C22: Fits strength in reducing ambiguity, speeding quote generation, and standardizing handoffs. | D22: You may inherit relationship-heavy revenue that resists systemization.
A23: 3 | B23: B2B services business with recurring ops chaos | C23: Good if there is a repetitive intake, scheduling, billing, compliance, or QA loop. | D23: Margin leakage can be hidden until after close.
A24: 4 | B24: Niche vertical SaaS with service wrapper | C24: Best if the software is underbuilt and the real product is workflow control. | D24: Pure SaaS may be too slow if it lacks operational leverage.
A25: 5 | B25: HR / workforce / compliance admin business | C25: Strong fit because you understand transaction-ready data, integration, and diligence workflows. | D25: Sales cycles and buyer conservatism can slow change.
A28: ACQUISITION TYPES (preserved)
A29: # | B29: Acquisition type | C29: Why it fits | D29: Target EBITDA | E29: Target EV / Note
A30: 1 | B30: Last-mile / dispatch-heavy logistics, 3PL, freight brokerage, specialized routing | C30: Direct match to quote-to-dispatch, pricing, status, crew/workforce orchestration, and operational AI mindset. | D30: $700k–$2.5M
A31: 2 | B31: Field-service or installation business with scheduling complexity | C31: Same bottleneck pattern as logistics: intake, dispatch, exceptions, capacity, and customer status. | D31: $500k–$1.8M
A32: 3 | B32: Business brokerage / advisory / transaction services with process drag | C32: Strong fit if the real problem is Excel, email, and manual reporting. | D32: $400k–$1.5M
A33: 4 | B33: HR, payroll, diligence, or workforce-integration services | C33: Fits transaction-readiness and integration-first thinking. | D33: $500k–$2.0M
A34: 5 | B34: Compliance / trust-sensitive monitoring business | C34: Good if signal quality matters more than feature breadth. | D34: $600k–$2.0M
A35: 6 | B35: Generic local service business without workflow leverage | C35: You can own it, but it is mostly management labor, not systems leverage. | D35: Any
A36: 7 | B36: Passive-style: parking lots, freight-yard, storage-yard, junk-yard | C36: Cash-flow asset, not product-led operating leverage. | D36: Varies | E36: Reject unless goal changes to cash-flow investing

Sheet 02_Target_Size_Bands
A1: TARGET SIZE BANDS — small individual acquirer
A2: Band | B2: SDE / EBITDA | C2: EV | D2: Notes
A3: Preferred | B3: $150K–$500K | C3: $500K–$2.0M | D3: Default search range
A4: Stretch | B4: $500K–$750K | C4: $2.0M–$3.0M | D4: Requires lender pre-qual + seller financing
A5: Avoid | B5: < $150K or > $750K EBITDA | C5: > $3.0M EV | D5: Too small (job) or too large without capital
A7: AFFORDABILITY CALCULATOR (fill yellow cells)
A8: Field | B8: Value | C8: Formula / Threshold | D8: Pass?
A9: Asking price / EV ($) | C9: INPUT
A10: Seller-reported SDE ($) | C10: INPUT
A11: Seller-reported EBITDA ($) | C11: INPUT
A12: Normalized buyer SDE ($) | C12: INPUT — use for multiples
A13: Normalized buyer EBITDA ($) | C13: INPUT — use for debt service
A14: Down payment % | B14: 0.2 | C14: INPUT (default 20%)
A15: Seller financing % | B15: 0.1 | C15: INPUT
A16: Interest rate (annual) | B16: 0.08 | C16: INPUT
A17: Loan term (years) | B17: 10 | C17: INPUT
A18: Liquid capital available ($) | C18: INPUT — fill in private copy only
A19: Minimum personal income needed ($/yr) | C19: INPUT
A21: EV / SDE (x) | B21: =IF(B12=0,"",B9/B12) | C21: =IF(B11=0,"",B9/B11)
A22: EV / EBITDA (x) | B22: =IF(B13=0,"",B9/B13) | C22: =IF(B13=0,"",B9/B13)
A23: Cash required ($) | B23: =B9*B14 | C23: =B9*B15
A24: Loan principal ($) | B24: =B9*(1-B14-B15) | C24: =B9*(1-B15-B16)
A25: Annual debt service ($) | B25: =IF(AND(B16>0,B17>0),ABS(PMT(B16,B17,-B24)),"") | C25: =IF(AND(B18>0,B19>0),PMT(B17,B19,-B22),"")
A26: DSCR (x) | B26: =IF(B25=0,"",B13/B25) | C26: =IF(B24=0,"",B13/B24)
A27: Post-debt owner cash flow ($) | B27: =IF(B13="","",B13-B25) | C27: =IF(B13="","",B13-B24)
A28: Size band | B28: =IF(OR(B13<150000,B13>750000,B9>3000000),"Avoid",IF(AND(B13>=150000,B13<=500000,B9<=2000000),"Preferred",IF(AND(B13>500000,B13<=750000,B9<=3000000),"Stretch","Review"))) | C28: formula
A29: Financing hard fail? | B29: =IF(OR(B18="",B23>B18,B26<1.25,B27<B19),"YES","NO") | C29: formula

Sheet 03_Operator_Readiness
A1: OPERATOR READINESS — default: NOT YET
A3: 1. Capital and financing
A4: Item | B4: Your answer | C4: Pass?
A5: Liquid equity for down payment ($) | C5: =IF(B5="","Incomplete",IF(OR(B5="NO",B5="Unknown"),"Fail","Pass"))
A6: Additional investable without ruin ($) | C6: =IF(B6="","Incomplete",IF(OR(B6="NO",B6="Unknown"),"Fail","Pass"))
A7: SBA 7(a) or seller note pre-qualified? | B7: Unknown | C7: =IF(B7="","Incomplete",IF(OR(B7="NO",B7="Unknown"),"Fail","Pass"))
A8: Max monthly debt service affordable ($) | C8: =IF(B8="","Incomplete",IF(OR(B8="NO",B8="Unknown"),"Fail","Pass"))
A9: Spouse/partner alignment on personal guarantee | B9: Unknown | C9: =IF(B9="","Incomplete",IF(OR(B9="NO",B9="Unknown"),"Fail","Pass"))
A11: 2. Runway and income pressure
A12: Item | B12: Your answer | C12: Pass?
A13: Months of personal runway at current burn | C13: =IF(B13="","Incomplete",IF(OR(B13="NO",B13="Unknown"),"Fail","Pass"))
A14: Minimum monthly income needed ($) | C14: =IF(B14="","Incomplete",IF(OR(B14="NO",B14="Unknown"),"Fail","Pass"))
A15: Can you go 6-12 months with $0 salary during search? | B15: NO | C15: =IF(B15="","Incomplete",IF(OR(B15="NO",B15="Unknown"),"Fail","Pass"))
A16: Fractional income still required ($/mo) | C16: =IF(B16="","Incomplete",IF(OR(B16="NO",B16="Unknown"),"Fail","Pass"))
A18: 3. Operator willingness (1-5)
A19: Activity | B19: Score (1-5) | C19: Pass?
A20: Reviewing P&L weekly | C20: =IF(B20="","",IF(B20>=3.5,"Pass","Fail"))
A21: Managing payroll / HR issues | C21: =IF(B21="","",IF(B21>=3.5,"Pass","Fail"))
A22: Vendor negotiations | C22: =IF(B22="","",IF(B22>=3.5,"Pass","Fail"))
A23: Seller transition meetings | C23: =IF(B23="","",IF(B23>=3.5,"Pass","Fail"))
A24: Firing underperformers | C24: =IF(B24="","",IF(B24>=3.5,"Pass","Fail"))
A25: Same customer problem 200 times | C25: =IF(B25="","",IF(B25>=3.5,"Pass","Fail"))
A26: Product/roadmap decisions post-close | C26: =IF(B26="","",IF(B26>=3.5,"Pass","Fail"))
A28: 4. Seller transition
A29: Item | B29: Plan | C29: Pass?
A30: Weeks seller stays post-close | C30: =IF(B30="","Incomplete",IF(OR(B30="NO",B30="Unknown"),"Fail","Pass"))
A31: Non-compete geography | C31: =IF(B31="","Incomplete",IF(OR(B31="NO",B31="Unknown"),"Fail","Pass"))
A32: Customer intro commitments | C32: =IF(B32="","Incomplete",IF(OR(B32="NO",B32="Unknown"),"Fail","Pass"))
A33: Your hours/week during transition | C33: =IF(B33="","Incomplete",IF(OR(B33="NO",B33="Unknown"),"Fail","Pass"))
A35: 5. Time budget
A36: Activity | B36: Hrs/week budget | C36: Actual (4-wk avg)
A37: Path B: founder outreach / apps | B37: 12
A38: Path A: Quotely distribution | B38: 7
A39: Acquisition: search + diligence | B39: 5
A41: 6. Professional support
A42: Resource | B42: Secured? | C42: Pass?
A43: SMB-focused attorney (LOI, APA) | B43: NO | C43: =IF(B43="","Incomplete",IF(OR(B43="NO",B43="Unknown"),"Fail","Pass"))
A44: QoE accountant or diligence help | B44: NO | C44: =IF(B44="","Incomplete",IF(OR(B44="NO",B44="Unknown"),"Fail","Pass"))
A45: Business broker relationship | B45: NO | C45: =IF(B45="","Incomplete",IF(OR(B45="NO",B45="Unknown"),"Fail","Pass"))
A46: SBA lender contact | B46: NO | C46: =IF(B46="","Incomplete",IF(OR(B46="NO",B46="Unknown"),"Fail","Pass"))
...

Sheet 04_Deal_Pipeline
A1: Deal ID | B1: Deal name | C1: Source | D1: Archetype | E1: Vertical | F1: Asking price ($) | G1: Seller SDE ($) | H1: Seller EBITDA ($) | I1: Normalized SDE ($) | J1: Normalized EBITDA ($) | K1: Seller financing % | L1: Status | M1: Notes | N1: Date added
A2: D001
A3: D002
A4: D003
A5: D004
A6: D005

Sheet 05_Deal_Scorecard
A1: Deal ID | B1: Deal name | C1: Operator fit (1-5) | D1: AI/product leverage (1-5) | E1: Financial feasibility (1-5) | F1: Owner dependence (1-5) | G1: Operating enjoyment (1-5) | H1: Strategic conflict (1-5) | I1: Weighted score | J1: Gate: improve? | K1: Gate: buy? | L1: Gate: operate 3yr? | M1: Day-to-day litmus? | N1: Financing documented? | O1: Path B displaced? | P1: Risk red flags (#) | Q1: All gates pass? | R1: Hard fail? | S1: Decision
B2: Weights | C2: 0.25 | D2: 0.2 | E2: 0.25 | F2: 0.15 | G2: 0.1 | H2: 0.05
A3: D001 | I3: =IF(COUNT(C3:H3)<6,"",ROUND(SUMPRODUCT(C3:H3,$C$2:$H$2)/SUM($C$2:$H$2),2)) | P3: ='06_Business_Risk_Diligence'!V3 | Q3: =IF(COUNTIF(J3:O3,"NO")>0,"NO","YES") | R3: =IF(OR(M3="NO",N3="NO",O3="YES",P3>=3),"YES","NO") | S3: =IF(AND(I3>=3.5,Q3="YES",R3="NO"),"Pursue",IF(OR(I3<2.5,R3="YES"),"Kill","Watch"))
A4: D002 | I4: =IF(COUNT(C4:H4)<6,"",ROUND(SUMPRODUCT(C4:H4,$C$2:$H$2)/SUM($C$2:$H$2),2)) | P4: ='06_Business_Risk_Diligence'!V4 | Q4: =IF(COUNTIF(J4:O4,"NO")>0,"NO","YES") | R4: =IF(OR(M4="NO",N4="NO",O4="YES",P4>=3),"YES","NO") | S4: =IF(AND(I4>=3.5,Q4="YES",R4="NO"),"Pursue",IF(OR(I4<2.5,R4="YES"),"Kill","Watch"))
A5: D003 | I5: =IF(COUNT(C5:H5)<6,"",ROUND(SUMPRODUCT(C5:H5,$C$2:$H$2)/SUM($C$2:$H$2),2)) | P5: ='06_Business_Risk_Diligence'!V5 | Q5: =IF(COUNTIF(J5:O5,"NO")>0,"NO","YES") | R5: =IF(OR(M5="NO",N5="NO",O5="YES",P5>=3),"YES","NO") | S5: =IF(AND(I5>=3.5,Q5="YES",R5="NO"),"Pursue",IF(OR(I5<2.5,R5="YES"),"Kill","Watch"))
A6: D004 | I6: =IF(COUNT(C6:H6)<6,"",ROUND(SUMPRODUCT(C6:H6,$C$2:$H$2)/SUM($C$2:$H$2),2)) | P6: ='06_Business_Risk_Diligence'!V6 | Q6: =IF(COUNTIF(J6:O6,"NO")>0,"NO","YES") | R6: =IF(OR(M6="NO",N6="NO",O6="YES",P6>=3),"YES","NO") | S6: =IF(AND(I6>=3.5,Q6="YES",R6="NO"),"Pursue",IF(OR(I6<2.5,R6="YES"),"Kill","Watch"))
A7: D005 | I7: =IF(COUNT(C7:H7)<6,"",ROUND(SUMPRODUCT(C7:H7,$C$2:$H$2)/SUM($C$2:$H$2),2)) | P7: ='06_Business_Risk_Diligence'!V7 | Q7: =IF(COUNTIF(J7:O7,"NO")>0,"NO","YES") | R7: =IF(OR(M7="NO",N7="NO",O7="YES",P7>=3),"YES","NO") | S7: =IF(AND(I7>=3.5,Q7="YES",R7="NO"),"Pursue",IF(OR(I7<2.5,R7="YES"),"Kill","Watch"))

Sheet 06_Business_Risk_Diligence
A1: Deal ID | B1: Deal name | C1: Owner is primary seller/dispatcher? | D1: No second-in-command? | E1: Key employee departure risk? | F1: High turnover / heroics? | G1: Underpaid relatives or misclassified contractors? | H1: SOP / tribal knowledge risk? | I1: Labor burden / OT exposure? | J1: Cannot explain gross margin by job type? | K1: Poor cash conversion? | L1: Systems messy and data absent? | M1: Deferred maintenance / claims? | N1: Top customer > 20% revenue? | O1: Top 3 customers > 40%? | P1: Founder owns all relationships? | Q1: Revenue re-sold each cycle? | R1: Paid ads with unclear CAC? | S1: Ops trust problems in reviews? | T1: Add-backs low confidence? | U1: Working capital surprise? | V1: Transition < 60 days seller support? | W1: Red flag count | X1: Risk band
A2: D001 | V2: =COUNTIF(C2:U2,"YES") | W2: =IF(V2>=5,"High",IF(V2>=2,"Medium","Low"))
A3: D002 | V3: =COUNTIF(C3:U3,"YES") | W3: =IF(V3>=5,"High",IF(V3>=2,"Medium","Low"))
A4: D003 | V4: =COUNTIF(C4:U4,"YES") | W4: =IF(V4>=5,"High",IF(V4>=2,"Medium","Low"))
A5: D004 | V5: =COUNTIF(C5:U5,"YES") | W5: =IF(V5>=5,"High",IF(V5>=2,"Medium","Low"))
A6: D005 | V6: =COUNTIF(C6:U6,"YES") | W6: =IF(V6>=5,"High",IF(V6>=2,"Medium","Low"))

Sheet 07_Diligence_Memo
A1: Deal ID | B1: Deal name | C1: Date | D1: Archetype | E1: Asking / SDE / EBITDA | F1: Why this could work (your wedge) | G1: Why it might fail | H1: Normalized buyer economics | I1: Transition plan (60+ days?) | J1: Compare to one week of Path B outbound | K1: Decision | L1: Next action

Sheet 08_Time_Budget
A1: Week ending | B1: Path B outbound (hrs) | C1: Path A Quotely (hrs) | D1: Acquisition (hrs) | E1: Total | F1: Kill flag?
E2: =SUM(B2:D2) | F2: =IF(AND(D2>8,B2<5),"YES — pause acquisition","NO")
E3: =SUM(B3:D3) | F3: =IF(AND(D3>8,B3<5),"YES — pause acquisition","NO")
E4: =SUM(B4:D4) | F4: =IF(AND(D4>8,B4<5),"YES — pause acquisition","NO")
E5: =SUM(B5:D5) | F5: =IF(AND(D5>8,B5<5),"YES — pause acquisition","NO")
E6: =SUM(B6:D6) | F6: =IF(AND(D6>8,B6<5),"YES — pause acquisition","NO")
E7: =SUM(B7:D7) | F7: =IF(AND(D7>8,B7<5),"YES — pause acquisition","NO")
E8: =SUM(B8:D8) | F8: =IF(AND(D8>8,B8<5),"YES — pause acquisition","NO")
E9: =SUM(B9:D9) | F9: =IF(AND(D9>8,B9<5),"YES — pause acquisition","NO")
E10: =SUM(B10:D10) | F10: =IF(AND(D10>8,B10<5),"YES — pause acquisition","NO")
E11: =SUM(B11:D11) | F11: =IF(AND(D11>8,B11<5),"YES — pause acquisition","NO")
E12: =SUM(B12:D12) | F12: =IF(AND(D12>8,B12<5),"YES — pause acquisition","NO")
E13: =SUM(B13:D13) | F13: =IF(AND(D13>8,B13<5),"YES — pause acquisition","NO")

Sheet 09_Decision_Log
A1: Date | B1: Deal ID | C1: Deal name | D1: Decision | E1: Weighted score | F1: Reason | G1: Next action | H1: Revisit date

Sheet 10_Ownership_Stress
A1: OWNERSHIP STRESS — financial + profile litmus (complete ownership-challenges.md §9 before Pursue)
A2: Deal ID
A3: Deal name
A5: FINANCIAL STRESS
A6: Purchase price / EV ($)
A7: Equity in ($)
A8: Annual debt service ($)
A9: Expected normalized SDE year 1 ($)
A10: SDE stress haircut (%) | B10: -20
A11: Additional haircut — key customer / seller early (%) | B11: 0
A12: Hours/week operator (planned)
A13: Hours/week operator (actual stress case)
A14: Path B income forgone ($/yr)
A15: Minimum income floor ($/yr)
A17: Stressed SDE ($) | B17: =IF(B9="","",B9*(1+B10/100)*(1+B11/100))
A18: Post-debt owner cash ($) | B18: =IF(OR(B17="",B8=""),"",B17-B8)
A19: DSCR (x) | B19: =IF(B8=0,"",B17/B8)
A20: Post-debt cash >= floor? | B20: =IF(B18="","",IF(B18>=B15,"YES","NO"))
A21: DSCR >= 1.25x? | B21: =IF(B19="","",IF(B19>=1.25,"YES","NO"))
A22: Hours overrun? | B22: =IF(AND(B12<>"",B13<>""),IF(B13>B12,"YES","NO"),"")
A24: PROFILE LITMUS
A25: Path retired for this deal? | B25: Neither
A26: Domain still ops-AI / logistics / field service? | B26: YES
A27: Role in year 1 | B27: Product-led improver
A28: Primary motive | B28: Ownership
A29: Path B outbound hrs (this week)
A30: Acquisition hrs (this week)
A31: Argue-both-sides done? (ownership-challenges.md §9) | B31: NO
A33: One-bet violation? | B33: =IF(B25="Neither","YES — stop","NO")
A34: Month-5 domain drift flag? | B34: =IF(B26="NO","YES","NO")
A35: GM trap flag? | B35: =IF(B27="Hands-on GM","YES — Watch/Kill unless hire-ops-mgr plan","NO")
A36: Escape/Prestige without Ownership? | B36: =IF(OR(B28="Escape",B28="Prestige"),"YES — favor Path B","NO")
A37: Kill-rule proximity? | B37: =IF(AND(B30>8,B29<5),"KILL RULE RISK","OK")
A38: Argue-both-sides required? | B38: =IF(B31="NO","BLOCK Pursue until §9 complete","OK")
A40: Overall profile litmus | B40: =IF(OR(B33="YES — stop",B34="YES",B35="YES — Watch/Kill unless hire-ops-mgr plan",B36="YES — favor Path B",B37="KILL RULE RISK",B38="BLOCK Pursue until §9 complete"),"FAIL","PASS")
A41: Financial stress pass? | B41: =IF(OR(B20="NO",B21="NO"),"FAIL","PASS")
A42: Recommend before Pursue | B42: =IF(OR(B40="FAIL",B41="FAIL"),"Watch or Kill","OK to score in 05_Deal_Scorecard")
A43: Guide: ACQUISITION/ownership-challenges.md — section 9 argue-both-sides required before Pursue
